<mujoco model="pupper_v3">
    <!-- 固定基座版本：base_link 没有 freejoint，适合单独检查四条腿的关节层级、网格和碰撞体。 -->
    <keyframe>
        <!-- 初始姿态。fixed 模型的 qpos 只有 12 个腿部关节角，对应 actuator 中的 12 路控制。 -->
        <key name="home" qpos="0.0 0.0 0.0 0.0 0.0 0.0 0.0 0.0 0.0 0.0 0.0 0.0"
            ctrl="0.0 0.0 0.0             0.0 0.0 0.0             0.0 0.0 0.0             0.0 0.0 0.0" />
    </keyframe>
    <asset>
        <!-- 背景和地面网格材质。fixed 模型主要用于查看本体，地面可在 viewer 中辅助判断朝向。 -->
        <texture type="skybox" builtin="gradient" rgb1=".3 .5 .7" rgb2="0 0 0" width="512"
            height="512" />
        <texture name="grid" type="2d" builtin="checker" width="512" height="512" rgb1=".2 .4 .6"
            rgb2=".4 .6 .8" />
        <material name="grid" texture="grid" texrepeat="1 1" texuniform="true" reflectance="0" />
    </asset>
    <sensor>
        <!-- 机身 IMU 相关传感器，挂在 worldbody 末尾的 body_imu_site 上。 -->
        <framequat name="body_quat" objtype="site" objname="body_imu_site" />
        <gyro name="body_gyro" site="body_imu_site" />
        <accelerometer name="body_acc" site="body_imu_site" />

        <!-- 下面这组提供全局位姿/速度读数，便于后续控制或调试脚本统一读取。 -->
        <framequat objtype="site" objname="body_imu_site" name="orientation" />
        <framepos objtype="site" objname="body_imu_site" name="global_position" />
        <framelinvel objtype="site" objname="body_imu_site" name="global_linvel" />
        <frameangvel objtype="site" objname="body_imu_site" name="global_angvel" />
    </sensor>
    <actuator>
        <!-- 12 个 general actuator 分别驱动四条腿的 3 个转动关节，顺序与 keyframe.ctrl 保持一致。 -->
        <!-- 前右腿：髋外展/内收、髋俯仰、膝关节。 -->
        <general joint="leg_front_r_1" name="leg_front_r_1" />
        <general joint="leg_front_r_2" name="leg_front_r_2" />
        <general joint="leg_front_r_3" name="leg_front_r_3" />

        <!-- 前左腿：与前右腿镜像，关节限位方向也随左右侧调整。 -->
        <general joint="leg_front_l_1" name="leg_front_l_1" />
        <general joint="leg_front_l_2" name="leg_front_l_2" />
        <general joint="leg_front_l_3" name="leg_front_l_3" />

        <!-- 后右腿。 -->
        <general joint="leg_back_r_1" name="leg_back_r_1" />
        <general joint="leg_back_r_2" name="leg_back_r_2" />
        <general joint="leg_back_r_3" name="leg_back_r_3" />

        <!-- 后左腿。 -->
        <general joint="leg_back_l_1" name="leg_back_l_1" />
        <general joint="leg_back_l_2" name="leg_back_l_2" />
        <general joint="leg_back_l_3" name="leg_back_l_3" />
    </actuator>
    <default>
        <!-- 默认 actuator 近似位置伺服：力矩 = 5 * ctrl - 5 * qpos - 0.1 * qvel，并限制在 +/-3。 -->
        <general forcerange="-3 3" forcelimited="true" biastype="affine" gainprm="5.0 0 0"
            biasprm="0 -5.0 -0.1" />


        <!-- 默认几何体不参与碰撞；只有显式 class="collision" 的 geom 会打开碰撞。 -->
        <geom condim="6" contype="0" conaffinity="0" />


        <!-- 简化碰撞体使用 group=3，视觉网格使用 group=1，便于在 viewer 里分组显示。 -->
        <default class="collision">
            <geom group="3" contype="0" conaffinity="1" solimp="0.015 1 0.015"
                friction="0.8 0.02 0.01" />
        </default>

        <!-- 所有关节默认是带限位的 hinge，并加入少量阻尼/摩擦避免纯理想关节过于抖动。 -->
        <joint armature="0.0016" type="hinge" damping="0.01" frictionloss="0.01" limited="true" />
    </default>
    <!-- 椭圆摩擦锥和较高的 impratio 用于让接触求解更稳定。 -->
    <option cone="elliptic" impratio="100" />
    <!-- 角度统一使用弧度，meshdir 指向相对本 XML 的 STL 目录。 -->
    <compiler angle="radian" meshdir="meshes/stl/" autolimits="true" />
    <asset>
        <!-- 机身和四条腿的 STL 网格。左右腿通过 scale 镜像复用同一套零件。 -->
        <mesh name="BodyV4v70_001" file="BodyV4v70_001.stl" />
        <mesh name="LegAssemblyForFlangedv26_001" file="LegAssemblyForFlangedv26_001.stl" />
        <mesh name="LegAssemblyForFlangedv26_002" file="LegAssemblyForFlangedv26_002.stl" />
        <mesh name="LegAssemblyForFlangedv26_003" file="LegAssemblyForFlangedv26_003.stl" />
        <mesh name="LegAssemblyForFlangedv26_010" file="LegAssemblyForFlangedv26_010.stl"
            scale="1 -1 1" />
        <mesh name="LegAssemblyForFlangedv26_011" file="LegAssemblyForFlangedv26_011.stl"
            scale="1 1 -1" />
        <mesh name="LegAssemblyForFlangedv26_012" file="LegAssemblyForFlangedv26_012.stl"
            scale="1 1 -1" />
        <mesh name="LegAssemblyForFlangedv26_005" file="LegAssemblyForFlangedv26_005.stl" />
        <mesh name="LegAssemblyForFlangedv26_006" file="LegAssemblyForFlangedv26_006.stl" />
        <mesh name="LegAssemblyForFlangedv26_007" file="LegAssemblyForFlangedv26_007.stl" />
        <mesh name="LegAssemblyForFlangedv26_013" file="LegAssemblyForFlangedv26_013.stl"
            scale="1 -1 1" />
        <mesh name="LegAssemblyForFlangedv26_014" file="LegAssemblyForFlangedv26_014.stl"
            scale="1 1 -1" />
        <mesh name="LegAssemblyForFlangedv26_015" file="LegAssemblyForFlangedv26_015.stl"
            scale="1 1 -1" />
    </asset>
    <worldbody>
        <!-- 机身根节点。fixed 模型没有 freejoint，因此 base_link 固定在世界坐标中的 pos。 -->
        <body name="base_link" pos="0 0 0.13" gravcomp="0">
            <!-- 机身惯量来自 CAD/转换结果；碰撞体用 box 简化，视觉体用 STL 网格。 -->
            <inertial pos="0.025 0 0.015" quat="0 0.677807 0 0.73524" mass="1.506"
                diaginertia="0.00854071 0.0085 0.00235929" />
            <geom size="0.04507 0.06379 0.129715" pos="0.02146 0 0.03345"
                quat="0.499998 -0.5 -0.500002 0.5" type="box" class="collision" />
            <geom quat="0.499998 -0.5 -0.500002 0.5" type="mesh" contype="0" conaffinity="0"
                group="1" density="0" mesh="BodyV4v70_001" />
            <!-- 前右腿：三段嵌套 body 对应三自由度串联链。 -->
            <body name="leg_front_r_1" pos="0.075 -0.0835 0" quat="0.707105 0.707108 0 0"
                gravcomp="0">
                <inertial pos="0 0 0" mass="0.18" diaginertia="7.4e-05 5.8e-05 4.8e-05" />
                <!-- 第 1 轴：髋外展/内收。 -->
                <joint name="leg_front_r_1" pos="0 0 0" axis="0 0 1" range="-1.22 2.51" />
                <geom pos="0 0 -0.028" quat="1.32679e-06 0 0 1" type="mesh" contype="0"
                    conaffinity="0" group="1" density="0" mesh="LegAssemblyForFlangedv26_001" />
                <body name="leg_front_r_2" pos="0 0 0"
                    quat="0.707107 2.24089e-06 -0.707107 4.83018e-06" gravcomp="0">
                    <inertial pos="0 -0.0334 0.05419" quat="0.903877 0.427791 0 0" mass="0.186"
                        diaginertia="0.000113 9.74951e-05 4.65049e-05" />
                    <!-- 第 2 轴：髋俯仰。 -->
                    <joint name="leg_front_r_2" pos="0 0 0" axis="0 0 1" range="-0.42 3.14" />
                    <geom size="0.025 0.015" pos="0 -0.0494 0.0685" quat="0.707105 0 0.707108 0"
                        type="cylinder" class="collision" />
                    <geom pos="-0.028 0 0" quat="-2.93388e-06 0.707108 2.26082e-06 0.707106"
                        type="mesh" contype="0" conaffinity="0" group="1" density="0"
                        mesh="LegAssemblyForFlangedv26_002" />
                    <body name="leg_front_r_3" pos="0 -0.0494 0.0685" quat="0.707105 0 0.707108 0"
                        gravcomp="0">
                        <inertial pos="0.03866 -0.03585 0.01833"
                            quat="0.270598 0.653281 -0.270598 0.653281" mass="0.05"
                            diaginertia="7.7e-05 7.55e-05 5.5e-06" />
                        <!-- 第 3 轴：膝关节。足端 sphere 同时作为简化碰撞体。 -->
                        <joint name="leg_front_r_3" pos="0 0 0" axis="0 0 1" range="-2.79 0.71" />
                        <geom size="0.01995" pos="0.06231 -0.06216 0.018" quat="1.32679e-06 0 0 1"
                            type="sphere" class="collision" />
                        <geom pos="0.0685 0.0494 -0.028" quat="1.32679e-06 0 0 1" type="mesh"
                            contype="0" conaffinity="0" group="1" density="0"
                            mesh="LegAssemblyForFlangedv26_003" />
                        <site name="leg_front_r_3_foot_site" pos="0.06231 -0.06216 0.018" />
                    </body>
                </body>
            </body>
            <!-- 前左腿：前右腿的镜像结构，注意 y 方向位置和关节限位已镜像。 -->
            <body name="leg_front_l_1" pos="0.075 0.0835 0" quat="0.707105 -0.707108 0 0"
                gravcomp="0">
                <inertial pos="0 0 0" mass="0.18" diaginertia="7.4e-05 5.8e-05 4.8e-05" />
                <joint name="leg_front_l_1" pos="0 0 0" axis="0 0 1" range="-2.51 1.22" />
                <geom pos="0 0 -0.028" quat="1.32679e-06 0 0 1" type="mesh" contype="0"
                    conaffinity="0" group="1" density="0" mesh="LegAssemblyForFlangedv26_010" />
                <body name="leg_front_l_2" pos="0 0 0"
                    quat="-3.89602e-06 0.707107 -1.29867e-06 -0.707107" gravcomp="0">
                    <inertial pos="0 -0.0334 0.05419" quat="0.903877 0.427791 0 0" mass="0.186"
                        diaginertia="0.000113 9.74951e-05 4.65049e-05" />
                    <joint name="leg_front_l_2" pos="0 0 0" axis="0 0 1" range="-3.14 0.42" />
                    <geom size="0.025 0.015" pos="0 -0.0494 0.0685" quat="0.707105 0 0.707108 0"
                        type="cylinder" class="collision" />
                    <geom pos="0.028 0 0" quat="-2.93388e-06 0.707108 2.26082e-06 0.707106"
                        type="mesh" contype="0" conaffinity="0" group="1" density="0"
                        mesh="LegAssemblyForFlangedv26_011" />
                    <body name="leg_front_l_3" pos="0 -0.0494 0.0685"
                        quat="9.38184e-07 -0.707108 9.38187e-07 0.707105" gravcomp="0">
                        <inertial pos="0.03866 0.03585 0.01833"
                            quat="0.653281 0.270598 -0.653281 0.270598" mass="0.05"
                            diaginertia="7.7e-05 7.55e-05 5.5e-06" />
                        <joint name="leg_front_l_3" pos="0 0 0" axis="0 0 1" range="-0.71 2.79" />
                        <geom size="0.01995" pos="0.06231 0.06216 0.018" quat="1.32679e-06 0 0 1"
                            type="sphere" class="collision" />
                        <geom pos="0.0685 -0.0494 -0.028"
                            quat="1.76029e-12 1.32679e-06 1 1.32679e-06" type="mesh" contype="0"
                            conaffinity="0" group="1" density="0"
                            mesh="LegAssemblyForFlangedv26_012" />
                        <site name="leg_front_l_3_foot_site" pos="0.06231 0.06216 0.018" />
                    </body>
                </body>
            </body>
            <!-- 后右腿：与前右腿结构相同，安装点移动到机身后侧。 -->
            <body name="leg_back_r_1" pos="-0.075 -0.0725 0" quat="0.707105 0.707108 0 0"
                gravcomp="0">
                <inertial pos="0 0 0" mass="0.18" diaginertia="7.4e-05 5.8e-05 4.8e-05" />
                <joint name="leg_back_r_1" pos="0 0 0" axis="0 0 1" range="-1.22 2.51" />
                <geom pos="0 0 -0.028" quat="1.32679e-06 0 0 1" type="mesh" contype="0"
                    conaffinity="0" group="1" density="0" mesh="LegAssemblyForFlangedv26_005" />
                <body name="leg_back_r_2" pos="0 0 0"
                    quat="0.707107 2.24089e-06 -0.707107 4.83018e-06" gravcomp="0">
                    <inertial pos="0 -0.0334 0.05419" quat="0.903877 0.427791 0 0" mass="0.186"
                        diaginertia="0.000113 9.74951e-05 4.65049e-05" />
                    <joint name="leg_back_r_2" pos="0 0 0" axis="0 0 1" range="-0.42 3.14" />
                    <geom size="0.025 0.015" pos="0 -0.0494 0.0685" quat="0.707105 0 0.707108 0"
                        type="cylinder" class="collision" />
                    <geom pos="-0.028 0 0" quat="-2.93388e-06 0.707108 2.26082e-06 0.707106"
                        type="mesh" contype="0" conaffinity="0" group="1" density="0"
                        mesh="LegAssemblyForFlangedv26_006" />
                    <body name="leg_back_r_3" pos="0 -0.0494 0.0685" quat="0.707105 0 0.707108 0"
                        gravcomp="0">
                        <inertial pos="0.03866 -0.03585 0.01833"
                            quat="0.270598 0.653281 -0.270598 0.653281" mass="0.05"
                            diaginertia="7.7e-05 7.55e-05 5.5e-06" />
                        <joint name="leg_back_r_3" pos="0 0 0" axis="0 0 1" range="-2.79 0.71" />
                        <geom size="0.01995" pos="0.06231 -0.06216 0.018" quat="1.32679e-06 0 0 1"
                            type="sphere" class="collision" />
                        <geom pos="0.0685 0.0494 -0.028" quat="1.32679e-06 0 0 1" type="mesh"
                            contype="0" conaffinity="0" group="1" density="0"
                            mesh="LegAssemblyForFlangedv26_007" />
                        <site name="leg_back_r_3_foot_site" pos="0.06231 -0.06216 0.018" />
                    </body>
                </body>
            </body>
            <!-- 后左腿：后右腿的镜像结构。 -->
            <body name="leg_back_l_1" pos="-0.075 0.0725 0" quat="0.707105 -0.707108 0 0"
                gravcomp="0">
                <inertial pos="0 0 0" mass="0.18" diaginertia="7.4e-05 5.8e-05 4.8e-05" />
                <joint name="leg_back_l_1" pos="0 0 0" axis="0 0 1" range="-2.51 1.22" />
                <geom pos="0 0 -0.028" quat="1.32679e-06 0 0 1" type="mesh" contype="0"
                    conaffinity="0" group="1" density="0" mesh="LegAssemblyForFlangedv26_013" />
                <body name="leg_back_l_2" pos="0 0 0"
                    quat="-3.89602e-06 0.707107 -1.29867e-06 -0.707107" gravcomp="0">
                    <inertial pos="0 -0.0334 0.05419" quat="0.903877 0.427791 0 0" mass="0.186"
                        diaginertia="0.000113 9.74951e-05 4.65049e-05" />
                    <joint name="leg_back_l_2" pos="0 0 0" axis="0 0 1" range="-3.14 0.42" />
                    <geom size="0.025 0.015" pos="0 -0.0494 0.0685" quat="0.707105 0 0.707108 0"
                        type="cylinder" class="collision" />
                    <geom pos="0.028 0 0" quat="-2.93388e-06 0.707108 2.26082e-06 0.707106"
                        type="mesh" contype="0" conaffinity="0" group="1" density="0"
                        mesh="LegAssemblyForFlangedv26_014" />
                    <body name="leg_back_l_3" pos="0 -0.0494 0.0685"
                        quat="9.38184e-07 -0.707108 9.38187e-07 0.707105" gravcomp="0">
                        <inertial pos="0.03866 0.03585 0.01833"
                            quat="0.653281 0.270598 -0.653281 0.270598" mass="0.05"
                            diaginertia="7.7e-05 7.55e-05 5.5e-06" />
                        <joint name="leg_back_l_3" pos="0 0 0" axis="0 0 1" range="-0.71 2.79" />
                        <geom size="0.01995" pos="0.06231 0.06216 0.018" quat="1.32679e-06 0 0 1"
                            type="sphere" class="collision" />
                        <geom pos="0.0685 -0.0494 -0.028"
                            quat="1.76029e-12 1.32679e-06 1 1.32679e-06" type="mesh" contype="0"
                            conaffinity="0" group="1" density="0"
                            mesh="LegAssemblyForFlangedv26_015" />
                        <site name="leg_back_l_3_foot_site" pos="0.06231 0.06216 0.018" />
                    </body>
                </body>
            </body>
            <!-- IMU site：传感器块通过 objname/site 引用这里的位置和姿态。 -->
            <site name="body_imu_site" pos="0.09 0 0.032" />
        </body>
        <!-- 调试用光源和跟随机身的相机。 -->
        <light name="spotlight" mode="targetbodycom" target="base_link" diffuse="0.9 0.9 0.9"
            specular="0.3 0.3 0.3" pos="0 -4 4" cutoff="100" />
        <camera name="tracking_cam" mode="targetbody" target="base_link" pos="0.5 -0.5 0.5" />
    </worldbody>
</mujoco>
